<?xml version="1.0"?>
<robot name="box_robot">

  <!-- Base Link -->
  <link name="base_link">
    <visual>
      <geometry>
        <box size="0.4 0.3 0.1"/>
      </geometry>
      <material name="blue">
        <color rgba="0 0 1 1"/>
      </material>
    </visual>
    <collision>
      <geometry>
        <box size="0.3 0.3 0.1"/>
      </geometry>
    </collision>
  <inertial>
    <origin xyz="0 0 0" rpy="0 0 0"/> <!-- Adjust if the center of mass is not at the geometric center -->
    <mass value="0.1"/> <!-- Mass of the link -->
    <inertia 
      ixx="0.0025" ixy="0" ixz="0"
      iyy="0.0033" iyz="0"
      izz="0.0033"/> <!-- Inertia tensor components calculated based on the box dimensions -->
  </inertial>
  </link>

  <!-- Wheels -->
<link name="wheel_front_left">
    <visual>
        <geometry>
            <cylinder radius="0.05" length="0.02"/>
        </geometry>
        <origin rpy="1.57079632679 0 0" />
        <material name="black"/>
    </visual>
    <collision>
        <geometry>
            <cylinder radius="0.05" length="0.02"/>
        </geometry>
        <origin rpy="1.57079632679 0 0" />
    </collision>
    <inertial>
      <origin xyz="0 0 0" rpy="0 0 0"/>
      <mass value="0.001"/>
      <inertia 
        ixx="0.0000020833" ixy="0" ixz="0"
        iyy="0.0000020833" iyz="0"
        izz="0.0000041667"/>
    </inertial>
</link>

<link name="wheel_front_right">
    <visual>
        <geometry>
            <cylinder radius="0.05" length="0.02"/>
        </geometry>
        <origin rpy="1.57079632679 0 0" />
        <material name="black"/>
    </visual>
    <collision>
        <geometry>
            <cylinder radius="0.05" length="0.02"/>
        </geometry>
        <origin rpy="1.57079632679 0 0" />
    </collision>

    <inertial>
      <origin xyz="0 0 0" rpy="0 0 0"/>
      <mass value="0.001"/>
      <inertia 
        ixx="0.0000020833" ixy="0" ixz="0"
        iyy="0.0000020833" iyz="0"
        izz="0.0000041667"/>
    </inertial>
</link>

<link name="wheel_rear_left">
    <visual>
        <geometry>
            <cylinder radius="0.05" length="0.02"/>
        </geometry>
        <origin rpy="1.57079632679 0 0" />
        <material name="black"/>
    </visual>
    <collision>
        <geometry>
            <cylinder radius="0.05" length="0.02"/>
        </geometry>
        <origin rpy="1.57079632679 0 0" />
    </collision>
    <inertial>
      <origin xyz="0 0 0" rpy="0 0 0"/>
      <mass value="0.001"/>
      <inertia 
        ixx="0.0000020833" ixy="0" ixz="0"
        iyy="0.0000020833" iyz="0"
        izz="0.0000041667"/>
    </inertial>
</link>

<link name="wheel_rear_right">
    <visual>
        <geometry>
            <cylinder radius="0.05" length="0.02"/>
        </geometry>
        <origin rpy="1.57079632679 0 0" />
        <material name="black"/>
    </visual>
    <collision>
        <geometry>
            <cylinder radius="0.05" length="0.02"/>
        </geometry>
        <origin rpy="1.57079632679 0 0" />
    </collision>
    <inertial>
      <origin xyz="0 0 0" rpy="0 0 0"/>
      <mass value="0.001"/>
      <inertia 
        ixx="0.0000020833" ixy="0" ixz="0"
        iyy="0.0000020833" iyz="0"
        izz="0.0000041667"/>
    </inertial>
</link>




  <!-- Joint definitions -->
  <!-- Adjusting origin z-value to lift the car by half the wheel size -->
  <!-- Front Left Wheel -->
<!-- Steering Joint for the Front Left Wheel -->
<joint name="joint_steering_front_left" type="revolute">
    <parent link="base_link"/>
    <child link="wheel_front_left"/>
    <origin xyz="0.18 0.18 -0.05" rpy="0 0 0"/> <!-- Adjust these values as needed -->
    <axis xyz="0 0 1"/> <!-- Axis of rotation (Z-axis in this case) -->
    <limit lower="-2.5" upper="2.5" effort="100" velocity="2.5"/> <!-- Adjust limits, effort, and velocity as needed -->
</joint>

<!-- Steering Joint for the Front Right Wheel -->
<joint name="joint_steering_front_right" type="revolute">
    <parent link="base_link"/>
    <child link="wheel_front_right"/>
    <origin xyz="0.18 -0.18 -0.05" rpy="0 0 0"/> <!-- Adjust these values as needed -->
    <axis xyz="0 0 1"/> <!-- Axis of rotation (Z-axis in this case) -->
    <limit lower="-2.5" upper="2.5" effort="100" velocity="2.5"/> <!-- Adjust limits, effort, and velocity as needed -->
</joint>

  <!-- Rear Left Wheel -->
  <joint name="joint_wheel_rear_left" type="continuous">
    <parent link="base_link"/>
    <child link="wheel_rear_left"/>
    <origin xyz="-0.18 0.18 -0.05" rpy="0 0 0"/>
        <axis xyz="0 1 0"/>
        <limit effort="100" velocity="10.0"/> 
  </joint>

  <!-- Rear Right Wheel -->
  <joint name="joint_wheel_rear_right" type="continuous">
    <parent link="base_link"/>
    <child link="wheel_rear_right"/>
    <origin xyz="-0.18 -0.18 -0.05" rpy="0 0 0"/>
        <axis xyz="0 1 0"/>
        <limit effort="100" velocity="10.0"/> 
  </joint>




  <!-- LiDAR -->
<!--   
  <link name="lidar_link">
    <visual>
      <geometry>
        <cylinder radius="0.05" length="0.1"/>
      </geometry>
      <material name="black"/>
    </visual>
    <inertial>
      <origin xyz="0 0 0" rpy="0 0 0"/>
      <mass value="0.00"/>
      <inertia ixx="0.00" ixy="0" ixz="0" iyy="0.00" iyz="0" izz="0.00"/>
    </inertial>
  </link>


  <joint name="joint_lidar" type="fixed">
    <parent link="base_link"/>
    <child link="lidar_link"/>
   
    <origin xyz="0 0 0.05" rpy="0 0 0"/>
  </joint> -->

</robot>
